Workbook

Sheet Summary
A1: HilotSpa — Progress Summary
A2: Live formulas over the Tasks and Bugs sheets. Ranges run to row 400 on purpose: they were pinned to the exact last row (132) and a task appended below it was silently left out of every count. Widened 2026-09-02.
A4: Sprint | B4: Total | C4: Done | D4: In Progress | E4: Not Started | F4: Blocked | G4: % Complete
A5: Sprint 0 | B5: =COUNTIF(Tasks!$A$5:$A$400,$A5) -> 30 | C5: =COUNTIFS(Tasks!$A$5:$A$400,$A5,Tasks!$E$5:$E$400,"Done") -> 25 | D5: =COUNTIFS(Tasks!$A$5:$A$400,$A5,Tasks!$E$5:$E$400,"In Progress") -> 0 | E5: =COUNTIFS(Tasks!$A$5:$A$400,$A5,Tasks!$E$5:$E$400,"Not Started") -> 5 | F5: =COUNTIFS(Tasks!$A$5:$A$400,$A5,Tasks!$E$5:$E$400,"Blocked") -> 0 | G5: =IFERROR($C5/$B5,0) -> 0.83333333
A6: Sprint 1 | B6: =COUNTIF(Tasks!$A$5:$A$400,$A6) -> 24 | C6: =COUNTIFS(Tasks!$A$5:$A$400,$A6,Tasks!$E$5:$E$400,"Done") -> 23 | D6: =COUNTIFS(Tasks!$A$5:$A$400,$A6,Tasks!$E$5:$E$400,"In Progress") -> 1 | E6: =COUNTIFS(Tasks!$A$5:$A$400,$A6,Tasks!$E$5:$E$400,"Not Started") -> 0 | F6: =COUNTIFS(Tasks!$A$5:$A$400,$A6,Tasks!$E$5:$E$400,"Blocked") -> 0 | G6: =IFERROR($C6/$B6,0) -> 0.95833333
A7: Sprint 2 | B7: =COUNTIF(Tasks!$A$5:$A$400,$A7) -> 48 | C7: =COUNTIFS(Tasks!$A$5:$A$400,$A7,Tasks!$E$5:$E$400,"Done") -> 46 | D7: =COUNTIFS(Tasks!$A$5:$A$400,$A7,Tasks!$E$5:$E$400,"In Progress") -> 1 | E7: =COUNTIFS(Tasks!$A$5:$A$400,$A7,Tasks!$E$5:$E$400,"Not Started") -> 0 | F7: =COUNTIFS(Tasks!$A$5:$A$400,$A7,Tasks!$E$5:$E$400,"Blocked") -> 0 | G7: =IFERROR($C7/$B7,0) -> 0.95833333
A8: Sprint 3 | B8: =COUNTIF(Tasks!$A$5:$A$400,$A8) -> 18 | C8: =COUNTIFS(Tasks!$A$5:$A$400,$A8,Tasks!$E$5:$E$400,"Done") -> 6 | D8: =COUNTIFS(Tasks!$A$5:$A$400,$A8,Tasks!$E$5:$E$400,"In Progress") -> 6 | E8: =COUNTIFS(Tasks!$A$5:$A$400,$A8,Tasks!$E$5:$E$400,"Not Started") -> 6 | F8: =COUNTIFS(Tasks!$A$5:$A$400,$A8,Tasks!$E$5:$E$400,"Blocked") -> 0 | G8: =IFERROR($C8/$B8,0) -> 0.33333333
A9: Sprint 4 | B9: =COUNTIF(Tasks!$A$5:$A$400,$A9) -> 16 | C9: =COUNTIFS(Tasks!$A$5:$A$400,$A9,Tasks!$E$5:$E$400,"Done") -> 1 | D9: =COUNTIFS(Tasks!$A$5:$A$400,$A9,Tasks!$E$5:$E$400,"In Progress") -> 1 | E9: =COUNTIFS(Tasks!$A$5:$A$400,$A9,Tasks!$E$5:$E$400,"Not Started") -> 14 | F9: =COUNTIFS(Tasks!$A$5:$A$400,$A9,Tasks!$E$5:$E$400,"Blocked") -> 0 | G9: =IFERROR($C9/$B9,0) -> 0.0625
A10: TOTAL | B10: =SUM(B5:B9) -> 136 | C10: =SUM(C5:C9) -> 101 | D10: =SUM(D5:D9) -> 9 | E10: =SUM(E5:E9) -> 25 | F10: =SUM(F5:F9) -> 0 | G10: =IFERROR($C10/$B10,0) -> 0.74264706
A12: Open bugs | B12: =COUNTIF(Bugs!$F:$F,"Open") -> 11
A13: Critical open | B13: =COUNTIFS(Bugs!$F:$F,"Open",Bugs!$E:$E,"Critical") -> 0

Sheet Tasks
A1: HilotSpa — Task Tracker
A2: Statuses: Not Started / In Progress / Done / Blocked / N/A (dropdown in column E)
A4: Sprint | B4: ID | C4: Task | D4: Detail | E4: Status | F4: Owner | G4: Notes
A5: Sprint 0 | B5: 0.1 | C5: Fix trivial model bugs | D5: FormsRepository return types, User.demographics OneToOne, massage table typo, durationMinute, compose.yaml space | E5: Done | F5: Liodoq | G5: Reviewed and confirmed correct.
A6: Sprint 0 | B6: 0.2 | C6: Invert Forms <-> PatientIntake to one-to-many | D6: A form must hold MANY pain points. Touches Forms, PatientIntake, FormsModel, both repositories, FormsServiceImpl, FormsTransformImpl. | E6: Done | F6: Liodoq | G6: Closed. B6-B11 all fixed. Aggregate-root design: Forms is the only door into pain points.
A7: Sprint 0 | B7: 0.3 | C7: Migrate all primary keys to UUID | D7: Highest-leverage item. Integer IDs collide across branch nodes and make P2P sync impossible. | E7: Done | F7: Claude | G7: All 36 files migrated. Domain Integers (painScore, coords, age, height, weight, durationMinute) intentionally left as Integer.
A8: Sprint 0 | B8: 0.4 | C8: Add security fields to User | D8: passwordHash, enabled, branch FK, role as @Enumerated enum CUSTOMER/STAFF/ADMIN. | E8: Done | F8: Liodoq | G8: passwordHash, enabled, branch FK, role as @Enumerated(EnumType.STRING) enum. Branch resolved in create + update.
A9: Sprint 0 | B9: 0.5 | C9: Add the missing core entities | D9: Appointment, Therapist, Room, ServiceProtocol, Contraindication, AuditLog. | E9: Done | F9: Liodoq | G9: ALL of 0.5 complete. 18 entities, 11 repositories. Therapist, Room, ServiceProtocol (+ProtocolRule), Appointment (+AppointmentStatus/PaymentStatus/BookingSource), AuditLog, ComplaintType. App boots clean against a live schema.
A10: Sprint 0 | B10: 0.6 | C10: Spring Security + JWT + RBAC | D10: Satisfies FR#4 and Process Rules #1 and #5. Staff restricted to their own Branch ID at query level. | E10: Done | F10: Liodoq+Claude | G10: Auth, RBAC endpoint rules, and query-level branch scoping all shipped (0.6a-0.6c-2). B29/B30 closed.
A11: Sprint 0 | B11: 0.7 | C11: Infra: Flyway, Redis, secrets | D11: Flyway so every node shares an identical schema. Redis into pom.xml + compose.yaml. | E11: Done | F11: Claude | G11: Closed 2026-08-30. Flyway owns the schema; Hibernate switched to ddl-auto=validate and PASSED against the live database on the first try, which also proves the V1 baseline dump is accurate. V1 is a pg_dump of the schema as ddl-auto left it (three lines stripped: \restrict / \unrestrict psql meta-commands that pg_dump 15.18 emits and JDBC cannot parse, and the search_path reset that would have broken Flyway's own INSERT into flyway_schema_history). Both settings are env-driven - FLYWAY_ENABLED / DDL_AUTO - so the rollback is deleting two lines from .env, no rebuild. THE TRAP: on Spring Boot 4, flyway-core alone is NOT enough. Boot 4 split auto-configuration into one module per technology, so FlywayAutoConfiguration ships with spring-boot-starter-flyway. With only flyway-core the library is present, the auto-configuration is not, and every spring.flyway.* property is an inert string - no error, no warning, no log line, the app starts perfectly and never migrates. Cost about 40 minutes of chasing a stale Docker image that was not stale. | PROVEN IN ANGER 2026-08-31, the very first entity change after the switch: Massage.imageName was added without a migration and all 33 tests errored with 'Schema validation: missing column [image_name] in table [massage]' - a refusal to start, naming the exact table and column. Under the old ddl-auto=update Hibernate would have silently added it on one machine and left every other node missing it, which is B66/B77/B85 exactly. Fixed by V3__service_photo.sql. Good defence answer: the schema is versioned and the system refuses to run against a database it does not recognise - and we have a real incident to describe, not a claim.
A12: Sprint 0 | B12: 0.8 | C12: Scaffold the Angular project | D12: Fresh Angular app + Tailwind, wired to the backend. | E12: Done | F12: Liodoq | G12: Angular 21.2 + Tailwind 4, committed 2169414 / d82f8ae.
A13: Sprint 1 | B13: 1.1 | C13: 2D body map component (front + back SVG) | D13: Angular canvas/SVG. Paper Scope: '2D Visualization of front and back body parts'. | E13: Done | G13: shared/body-map — front and back SVG, percentage coordinates.
A14: Sprint 1 | B14: 1.2 | C14: Tap-to-place pain markers with severity | D14: Marker stores bodyView, anatomicalRegion, x, y, painScore 1-10. | E14: Done | G14: Tap to place, drag-free severity 1-10, remove, region auto-guess with an editable dropdown.
A15: Sprint 1 | B15: 1.3 | C15: 25-item complaint checklist | D15: Neck Pain ... TMJ Disorder + Others. Exact list from paper Scope + Appendix A. | E15: Done | G15: All 24 conditions + Others, verbatim from Appendix A, with live filtering.
A16: Sprint 1 | B16: 1.4 | C16: Pain vs Leisure fork on first screen | D16: Leisure path completes an assessment in one tap. Resolves the Process Rule #2 contradiction. | E16: Done | G16: C2 built. intent is recorded on Forms (H6), so the leisure path is a real, distinguishable record.
A17: Sprint 1 | B17: 1.5 | C17: Age-inclusive styling | D17: High contrast, >=18px base font, >=44px touch targets, warm palette, simplified navigation. | E17: Done | G17: 13 tokens, 68px targets, 6.88:1 brand contrast, prefers-reduced-motion. Evidence in paper-deltas SS I.
A18: Sprint 1 | B18: 1.6 | C18: Demographics capture screen | D18: Age, sex, status, height, weight, birthdate. Mirrors the paper intake form. | E18: Done | G18: C3 built. NOTE: a CUSTOMER cannot save it yet - see B43.
A19: Sprint 1 | B19: 1.7 | C19: Submit form + pain points to backend | D19: Single POST carrying form and its painPoints array. | E19: Done | G19: Proven 2026-08-25 - a real assessment reached Postgres and came back out through the assistant (see 1.16).
A20: Sprint 2 | B20: 2.1 | C20: Redis temporary resource locking | D20: Lock therapist + room + slot with a TTL while booking is in progress. | E20: N/A | G20: SUPERSEDED by 2.37, 2026-08-30. Process Rule #4 needed a guarantee that two transactions cannot award the same therapist or room; that guarantee now lives in Postgres as EXCLUDE USING gist, partial on blocking statuses, half-open ranges. A database constraint is strictly stronger than a Redis lock - it cannot be bypassed by a caller that forgets to take it, and it survives a cache restart. Marked N/A rather than Not Started so the sprint total is not understated at the defence.
A21: Sprint 2 | B21: 2.2 | C21: n8n workflow scaffolding | D21: Assemble prompt -> call Gemini -> validate response -> write booking. | E21: Done | G21: Two published workflows in n8n/, version-controlled as files: hilotspa-recommend and hilotspa-chat.
A22: Sprint 2 | B22: 2.3 | C22: Gemini call with constrained structured output | D22: recommendedServiceId is an enum of real catalog UUIDs so the model cannot invent a service. | E22: Done | G22: The model never names a service; it ranks ids Spring sent. n8n drops any id it did not receive, then Java re-validates. Two independent checks, and rejectedCount makes the discard rate countable.
A23: Sprint 2 | B23: 2.4 | C23: Contraindication filter applied BEFORE the AI call | D23: Deterministic table authored by the spa. AI only ever sees an already-safe list. | E23: Done | G23: MECHANISM DONE and verified: allowedServicesFor() filters ServiceProtocol before the n8n call, and the excluded count is shown to the client. THE RULES THEMSELVES DO NOT EXIST YET - 0 CONTRAINDICATED rows, so it currently excludes nothing. See 4.13 and R18.
A24: Sprint 2 | B24: 2.5 | C24: Chat UI | D24: Task-first, short structured replies, not chatty. Supported by [10]. | E24: Done | G24: Real relay as of 2026-08-25. Replies come from Vertex through Spring, quoting price and duration read from Postgres.
... A28: Sprint 3 | B28: 3.1 | C28: Append-only sync_log table | D28: nodeId + monotonic sequenceNo per node. Peers pull everything after seq N. | E28: Not Started | G28: Requires UUID keys (0.3).
A29: Sprint 3 | B29: 3.2 | C29: Node registry | D29: Each node knows its peers' addresses and last-seen sequence numbers. | E29: Not Started
A30: Sprint 3 | B30: 3.3 | C30: Pull-based gossip between peers | D30: Broadcast local changes, pull remote changes, apply to read-only replicas. | E30: Not Started | G30: FR#3
A31: Sprint 3 | B31: 3.4 | C31: Enforce single-writer-per-partition | D31: A node may only write resources it owns. Makes split-brain structurally impossible. | E31: In Progress | G31: Half of it is now enforced, and it is the half that can be. 2026-08-30: a therapist and a room each belong to exactly one branch (schema), and Flyway migration V2 adds EXCLUDE constraints so the database itself refuses an overlapping write. Within a node, single-writer is a mechanism rather than a convention. What remains is the cross-node half - a node refusing to write a resource it does not own - which needs the node registry (3.2) to exist first.
A32: Sprint 3 | B32: 3.5 | C32: Admin aggregated dashboard | D32: Global view across all branch nodes. | E32: In Progress | G32: A1 now counts live: bookings today/this week, assessments, therapists available, rooms, and assistant reliability read out of audit_log. Reports ONE node and says on screen that the registry is Sprint 3 - a second node drawn as offline would be a picture of a feature.
A33: Sprint 3 | B33: 3.6 | C33: Context switch into a specific branch | D33: Admin loads a branch's local dashboard. | E33: In Progress | G33: A2 built (context switching UI). Opening a branch reuses S1.
A34: Sprint 3 | B34: 3.7 | C34: Offline mode + visible status banner | D34: Branch keeps booking its own resources with no internet. Syncs on reconnect. | E34: Done | G34: Built 2026-08-30. core/connectivity.ts tracks TWO states, not one: `offline` from the browser's own events, and `unreachable` set only after a request returned status 0 - no HTTP response at all, as opposed to a 500 which means the server is alive and struggling. The distinction is the architecture in one banner: at the branch, staff reach their node over the LAN, so an INTERNET outage does not touch them - only their node going down does. Wired through the HTTP interceptor, which is the only place that sees every request and its outcome. Real banner in AppNav (customer) and DashShell (staff/admin), ABOVE the existing simulated-offline banner so the two can never be confused. Wording promises nothing about queueing, because there is no service worker and no local write queue - it says only what is true: a booking already made is on the server and unaffected.
A35: Sprint 3 | B35: 3.8 | C35: Global configuration broadcast | D35: Admin edits service menu / pricing, broadcast to all nodes. | E35: In Progress | G35: A4 reads and writes real service_protocol rows and logs PROTOCOL_EDITED. No broadcast mechanism yet - there is only one node to broadcast to.
A36: Sprint 3 | B36: 3.9 | C36: Audit log generation | D36: Per-node audit trail, aggregated for the admin. | E36: Done | G36: AuditLog is written by the booking, assistant, resource, protocol and outcome paths, and A5 reads it. Cross-node aggregation is 3.3.
A37: Sprint 3 | B37: 3.10 | C37: Stand up a SECOND node for the demo | D37: Second laptop or VM on the same LAN. You cannot demo decentralization with one node. | E37: Not Started | G37: Research locale names only one branch. See Defense Risks R5.
A38: Sprint 4 | B38: 4.1 | C38: Pre-implementation baseline timing | D38: Stopwatch ~20 real clients on the manual workflow BEFORE deployment. | E38: Not Started | G38: Paper claims 10-15 min manual intake. Prove it.
A39: Sprint 4 | B39: 4.2 | C39: TAM instrument (validated item set) | D39: Perceived Ease of Use + Perceived Usefulness, 5-point Likert. Use Davis/Venkatesh items and cite. | E39: Not Started
A40: Sprint 4 | B40: 4.3 | C40: CUQ instrument (real 16 items) | D40: Holmes et al. 16 alternating positive/negative items with the official 0-100 scoring formula. | E40: Not Started | G40: Do not invent your own questions.
A41: Sprint 4 | B41: 4.4 | C41: Technical & Operational Checklist | D41: AI-vs-therapist agreement rate, 0 out-of-catalog outputs, sync latency, offline recovery time. | E41: Not Started | G41: This is how you measure 'AI reliability'. See Defense Risks R6.
A42: Sprint 4 | B42: 4.5 | C42: Run UAT with customers, staff, admin | D42: Non-probability sampling across the three role groups. | E42: Not Started
A43: Sprint 4 | B43: 4.6 | C43: Weighted mean + frequency analysis | D43: Apply the paper's Likert interpretation guide. | E43: Not Started
A44: Sprint 4 | B44: 4.7 | C44: Write Chapter IV | D44: Before/after tables, TAM/CUQ results, checklist results. | E44: Not Started
...

Sheet Bugs
A1: HilotSpa — Bug & Finding Log
A3: ID | B3: Task | C3: Where | D3: Problem | E3: Severity | F3: Status | G3: Notes
A4: B1 | B4: 0.1 | C4: FormsRepository | D4: findBy* returned List<Repository> instead of List<Forms> | E4: Critical | F4: Fixed | G4: Would fail at application startup.
A5: B2 | B5: 0.1 | C5: User.java | D5: @OneToOne mapped to a List<Demographics> | E5: Critical | F5: Fixed
A6: B3 | B6: 0.1 | C6: Massage.java | D6: Table name typo "masasage" | E6: Minor | F6: Fixed
A7: B4 | B7: 0.1 | C7: Massage.java | D7: LocalTime used to represent a duration | E7: Major | F7: Fixed | G7: Now durationMinute.
A8: B5 | B8: 0.1 | C8: compose.yaml | D8: Leading space parsed into the JDBC URL | E8: Major | F8: Fixed
A9: B6 | B9: 0.2 | C9: Forms / PatientIntake | D9: Relationship inverted; capped every form at one pain point | E9: Critical | F9: Fixed | G9: Entities and models now correct.
A10: B7 | B10: 0.2 | C10: Forms.java | D10: OLD @ManyToOne PatientIntake field was never deleted | E10: Critical | F10: Fixed | G10: Fixed. Circular NOT NULL FK resolved.
A11: B8 | B11: 0.2 | C11: FormsRepository | D11: findByPatientIntakeId still present | E11: Critical | F11: Fixed | G11: Will not resolve once B7 is fixed. Delete the method.
A12: B9 | B12: 0.2 | C12: PatientIntakeTransformImpl | D12: bodyView not mapped in either direction | E12: Major | F12: Fixed | G12: Body view was silently lost on every save and read. Mapped both directions.
A13: B10 | B13: 0.2 | C13: FormsTransformImpl | D13: formsModel.setId() never called | E13: Major | F13: Fixed | G13: Frontend gets no form ID back.
A14: B11 | B14: 0.2 | C14: PatientIntake service/controller | D14: create + update endpoints still exist | E14: Major | F14: Fixed | G14: Done. createPatientIntake/updatePatientIntake removed from service, impl, and controller.
A15: B12 | B15: - | C15: MassageRepository | D15: findByPrice returns Optional but price is not unique | E15: Major | F15: Fixed | G15: findByPrice removed entirely; lookup is now by UUID id via JpaRepository.
A16: B13 | B16: 0.3 | C16: All entities | D16: Integer IDENTITY primary keys | E16: Critical | F16: Fixed | G16: UUID primary keys across all entities. GenerationType.UUID.
A17: B14 | B17: 0.6 | C17: Whole backend | D17: No Spring Security, no authentication at all | E17: Critical | F17: Fixed | G17: Resolved by 0.6a-0.6c-1: Spring Security 7 + OAuth2 resource server, BCrypt hashing, JWT issuance, endpoint role rules. Remaining query-level scoping tracked separately as B29/B30.
A18: B15 | B18: 0.7 | C18: git history | D18: DB password admin1234 committed | E18: Minor | F18: Mitigated | G18: .env now gitignored. Change the actual DB password.
A19: B16 | B19: - | C19: Repo | D19: CRLF line endings make every diff unreadable | E19: Minor | F19: Fixed | G19: Fixed: .gitattributes now has * text=auto eol=lf.
A20: B17 | B20: 0.2 | C20: FormsServiceImpl | D20: Unused PatientIntakeRepository autowire + import | E20: Minor | F20: Fixed | G20: Removed during 0.3 sweep.
... A136: B133 | B136: 1.17 | C136: pages/service-detail book() + core/catalogue.store.ts load() | D136: A client who registered, was signed in, and tapped "Book this" was sent to the REGISTER page. book() asked cat.anonymous() - which describes how the MENU was fetched, not who is reading it. Underneath: load() returns early while loaded() is true, and loadPublic() sets loaded=true, so once a visitor has browsed the menu the token is never consulted again for the rest of the session. force and clear() were both written for exactly this case and neither was ever called by anything. The button was the mild half: a signed-in client kept being served the PUBLIC menu, whose entries all carry suitable=true because nothing was judged - while the service page tells them it "says plainly whether this treatment is advised for you". A claim about a judgement that was never made, which is the B91 class of untruth the store's own comment warns about. | E136: Major | F136: Fixed (built, unverified) | G136: Found 2026-09-15 by a real client (Keneth) on the LIVE site, on the primary path, within five minutes - a defect neither Liodoq nor Claude hit in a week, because both had accounts with demographics already cached. This is the argument for task 4.5 in miniature. Fixed in two places: book() now asks auth.token(); CatalogueStore gained a constructor effect that clears the cache whenever the token changes (invalidate only, never re-fetch - every screen calls load() on init and an effect firing requests on a token change becomes a mystery double-load later). LESSON, general: a cached view of the world must be invalidated when identity changes, or every "is this suitable for you?" on screen is about a different person than the one reading it.

Sheet Defense Risks
A1: HilotSpa — Defense Risk Register
A2: The paper cannot be edited. These are the contradictions a panelist may find, and how the BUILD resolves each one.
A4: ID | B4: Area | C4: Risk / Contradiction in the frozen paper | D4: Engineered resolution | E4: Where it lands | F4: Status
A5: R1 | B5: Architecture | C5: Offline survival (NFR#1) and guaranteed no double-booking (Process Rule #4) are contradictory under CAP. | D5: Partition write authority by physical resource ownership. A therapist/room belongs to exactly one branch, so cross-branch conflict cannot exist. Each node is sole writer for its own resources; peers hold read-only replicas. | E5: Sprint 3.4 | F5: Open
A6: R2 | B6: Requirements | C6: Process Rule #2 locks the chatbot until pre-assessment completes, but Significance promises leisure clients can bypass the forms. | D6: First screen forks: 'I have pain' vs 'I'm here to relax'. The leisure path still WRITES a completed assessment record in one tap. The gate is on completion, not length. | E6: Sprint 1.4 | F6: Resolved
A7: R3 | B7: AI Integrity | C7: Paper claims n8n is a 'strict filtering layer' preventing hallucinated medical advice. n8n is an orchestrator and does no such thing by itself. | D7: Give n8n three concrete jobs: (1) assemble prompt from DB only, (2) constrained structured output where serviceId is an enum of real catalog IDs, (3) post-validate against the catalog and reject anything else. VERIFIED LIVE: n8n drops any serviceId Spring did not send, then Java re-validates independently. rejectedCount is written to audit_log per call, so the discard rate is a query rather than a claim. | E7: Sprint 2.3 | F7: Mitigated
A8: R4 | B8: Ethics / Scope | C8: Process Rule #3 excludes contraindicated services, but the Delimitation says no medical advice. Excluding a service on health grounds IS a clinical decision. | D8: Contraindication rules authored and signed off by the spa's bone setter, stored in a DB table, applied in Java BEFORE the AI is called. Put the signed table in the appendix. | E8: Sprint 2.4 | F8: Mitigated
A9: R5 | B9: Evaluation | C9: Research locale names only one branch, but the decentralization claim needs at least two nodes. | D9: Run a second node on a laptop or VM on the same LAN. Demo sync by physically unplugging the network. Rehearse it. | E9: Sprint 3.10 | F9: Open
A10: R6 | B10: Evaluation | C10: Objective 4 says evaluate 'AI reliability', but CUQ measures perceived usability, not reliability. | D10: Add an objective measure to the Technical & Operational Checklist: agreement rate between the AI recommendation and a therapist's blind independent recommendation over >=30 trials, plus 0 out-of-catalog outputs. | E10: Sprint 4.4 | F10: Open
A11: R7 | B11: Scope | C11: Significance promises owners can monitor revenue, but the Delimitation excludes payment processing. | D11: Appointment snapshots the service price at booking. Staff mark PAID_AT_COUNTER. Revenue = sum of completed appointments. No payment processing involved. | E11: Sprint 0.5 | F11: Resolved
A12: R8 | B12: Presentation | C12: Figures 8.1 and 8.2 are both captioned 'Sprint 2'. Two tables are both numbered as Gap Analysis but the TOC lists one. References [12] and [34] are the same paper. | D12: Cosmetic. Fix if the adviser still permits caption-level edits; otherwise be ready to acknowledge it. | E12: Paper | F12: Open
A13: R9 | B13: Scope | C13: Appendix A has two halves. The bottom half is the bone setter own working sheet - spine chart C1-L5, the ADJUSTMENTS grid, the findings table. None of it is digitised, and a panelist who has seen the form will ask where it went. | D13: State the boundary explicitly: the system digitises the client-completed portion. S4 covers the findings table and BEFORE/AFTER pain; the adjustment record stays on paper for this study. | E13: Paper Ch.3 + S4 | F13: Open
A14: R10 | B14: Presentation | C14: The establishment trades as Knead Wellness Spa. The paper, the signed permission letter, and the running UI each use a different name. | D14: Adviser picks one convention. Safer option: registered name with a parenthetical on first mention. | E14: Paper SS A3 | F14: Open
A15: R11 | B15: Ethics | C15: A researcher shares a surname with the owners. Undisclosed, this looks like concealment; disclosed, it is routine. | D15: One sentence in the Research Locale section, plus the bias controls already in place (clock-time-only observation, practitioner-signed protocol). | E15: Paper SS A4 | F15: Open
... A24: R20 | B24: Evaluation | C24: The outcome loop now WORKS but has produced no data. painScoreAfter can only be written after a human closes off a real visit, and no real visit has been closed off. Chapter IV's before/after claim currently rests on a mechanism with zero rows behind it - the same shape of problem as R18, one layer further out. | D24: Two moves, and the first is free. (1) Close off the test bookings already sitting unanswered in the database - the new S2 calendar finds them - so the screens and the report have real rows in them at the demo. (2) Get one real visit closed off and re-scored at the spa before the defence; one honest pair beats a hundred seeded ones, and the mechanism is small enough to walk a staff member through in five minutes. | E24: Sprint 2.46 / 4.5 | F24: Open
